Workbook

Sheet Synthèse
A1: TikTok : ce qui distingue les contenus et créateurs performants
A4: 1 · LE SUCCÈS, DÉFINI
A5: Succès = portée ET engagement. Portée : vues ≥ médiane du fichier. Engagement : (J’aime + commentaires + partages) ÷ vues ≥ médiane. Les vues seules favorisent les gros comptes ; le taux d’engagement dit si le public réagit.
A6: ="Preuve : sur "&SUM(Succès!C17:C20)&" vidéos en tendance, seules "&Succès!C17&" cumulent les deux ; "&Succès!C19&" ont de la portée sans engagement et "&Succès!C18&" l’inverse." -> Preuve : sur 100 vidéos en tendance, seules 30 cumulent les deux ; 20 ont de la portée sans engagement et 20 l’inverse.
A8: =Succès!E10 -> 0.10677181 | B8: =Succès!D17 -> 0.3 | C8: =Facteurs!D6 -> 1.8961265 | D8: =Succès!E10/Succès!E12 -> 1.5954914 | E8: =Facteurs!E17 -> 0.19109258
A9: Taux d’engagement médian des vidéos en tendance (trending_videos) | B9: des vidéos en tendance (trending_videos) cumulent portée et engagement (« succès complet ») | C9: Taux de J’aime des vidéos à succès, par rapport aux autres (trending_videos) | D9: Engagement du contenu de créateurs vs contenu du compte officiel (trending_videos1 & tiktok_collected_videos) | E9: Engagement médian des comptes de moins d’1 M d’abonnés (contre 14–15 % pour les plus gros) (tiktok_funny_hashtag_videos)
A11: 2 · CE QUI DISTINGUE LES MEILLEURS (chiffre clé et lecture)
A12: Facteur | B12: Chiffre clé | D12: Ce que cela signifie
A13: Réaction du public | B13: ="J’aime ÷ vues : "&ROUND(Facteurs!B6*100,1)&" % pour les succès contre "&ROUND(Facteurs!C6*100,1)&" % (× "&ROUND(Facteurs!D6,1)&")" -> J’aime ÷ vues : 14,6 % pour les succès contre 7,7 % (× 1,9) | D13: Ce qui sépare les meilleurs : une vidéo que le public aime et commente davantage ; les partages ne font pas la différence.
A14: Réglages techniques | B14: ="Durée "&ROUND(Facteurs!B9,0)&" s vs "&ROUND(Facteurs!C9,0)&" s ; hashtags "&ROUND(Facteurs!B10,0)&" vs "&ROUND(Facteurs!C10,0)&" ; légende "&ROUND(Facteurs!B11,0)&" vs "&ROUND(Facteurs!C11,0)&" car." -> Durée 12 s vs 11 s ; hashtags 3 vs 3 ; légende 49 vs 46 car. | D14: Aucun effet visible : ce n’est pas la mécanique de la vidéo qui fait la performance.
A15: Hashtags génériques (#fyp, #viral…) | B15: ="Présents dans "&ROUND(Facteurs!B12*100,0)&" % des succès contre "&ROUND(Facteurs!C12*100,0)&" % des autres" -> Présents dans 27 % des succès contre 49 % des autres | D15: Pas un levier : les vidéos à succès en utilisent moins.
A16: Thème du contenu | B16: ="Engagement médian : food "&ROUND(Catégories!F9*100,1)&" % · famille "&ROUND(Catégories!F8*100,1)&" % · humour "&ROUND(Catégories!F6*100,1)&" %" -> Engagement médian : food 16,2 % · famille 13,5 % · humour 7,9 % | D16: L’humour porte la plus grosse portée mais engage le moins ; famille et food engagent davantage (food : 7 vidéos, dominées par un créateur).
A17: Taille de l’audience | B17: ="< 1 M abonnés : "&ROUND(Facteurs!E17*100,1)&" % ; > 5 M : "&ROUND(Facteurs!E19*100,1)&" % ; vues par abonné "&ROUND(Facteurs!G17,0)&" vs "&ROUND(Facteurs!G19,0) -> < 1 M abonnés : 19,1 % ; > 5 M : 15,4 % ; vues par abonné 112 vs 6 | D17: Les petits comptes engagent le plus : être gros ne suffit pas, être petit ne veut pas dire pas ou moins de succès.
A18: Contenu de créateurs vs de marque | B18: ="Créateurs "&ROUND(Succès!E10*100,1)&" % vs compte officiel "&ROUND(Succès!E12*100,1)&" %" -> Créateurs 10,7 % vs compte officiel 6,7 % | D18: Le contenu de créateurs engage environ 1,6 fois plus que le contenu institutionnel (réserve : un seul compte officiel).
A20: 3 · QUI DOMINE CHAQUE CATÉGORIE
A21: ="Humour : "&ROUND(Catégories!E6*100,0)&" % des vues, mais engagement médian de "&ROUND(Catégories!F6*100,1)&" % (le plus bas). Domine par la portée." -> Humour : 26 % des vues, mais engagement médian de 7,9 % (le plus bas). Domine par la portée.
A22: ="Food & lifestyle : engagement médian "&ROUND(Catégories!F9*100,1)&" %, "&ROUND(Catégories!G9*100,0)&" % de vidéos en succès complet (7 vidéos, dominées par un seul créateur). Famille & enfants : "&ROUND(Catégories!F8*100,1)&" % avec une portée élevée." -> Food & lifestyle : engagement médian 16,2 %, 71 % de vidéos en succès complet (7 vidéos, dominées par un seul créateur). Famille & enfants : 13,5 % avec une portée élevée.
A23: ="Non classé : "&ROUND(Catégories!E11*100,0)&" % des vues, thème inconnu (légende vide ou sans mot-clé) : limite de la classification, voir onglet Catégories." -> Non classé : 46 % des vues, thème inconnu (légende vide ou sans mot-clé) : limite de la classification, voir onglet Catégories.
A25: 4 · QUI CONTACTER EN PRIORITÉ (liste complète : onglet Contacts)
A26: Compte | B26: Source | C26: Taux d’engagement | D26: Vues cumulées | E26: Thème (tendance) / abonnés (hashtag)
A27: =Contacts!B10 -> @bts_official_bighit | B27: Tendance | C27: =Contacts!F10 -> 0.3609176 | D27: =Contacts!E10 -> 26700000 | E27: =Contacts!C10 -> Musique & danse
A28: =Contacts!B11 -> TND-010 | B28: Tendance | C28: =Contacts!F11 -> 0.25065765 | D28: =Contacts!E11 -> 73900000 | E28: =Contacts!C11 -> Food & lifestyle
A29: =Contacts!B12 -> TND-039 | B29: Tendance | C29: =Contacts!F12 -> 0.23800709 | D29: =Contacts!E12 -> 14100000 | E29: =Contacts!C12 -> Non classé
A30: =Contacts!B24 -> HSH-042 | B30: Hashtag humour | C30: =Contacts!F24 -> 0.29521528 | D30: =Contacts!E24 -> 28800000 | E30: =Contacts!C24 -> 499800
A31: =Contacts!B25 -> HSH-077 | B31: Hashtag humour | C31: =Contacts!F25 -> 0.25846209 | D31: =Contacts!E25 -> 27700000 | E31: =Contacts!C25 -> 958100
A32: =Contacts!B26 -> HSH-013 | B32: Hashtag humour | C32: =Contacts!F26 -> 0.25637093 | D32: =Contacts!E26 -> 46100000 | E32: =Contacts!C26 -> 144200
A34: 5 · À RETENIR AVANT DE DÉCIDER
A35: • Aucune vidéo peu performante dans les extraits : on compare des succès entre eux, on ne sait pas ce qui sépare un succès d’un échec.
A36: • Corrélations, pas causalité ; aucun résultat business (ventes, notoriété). Données de 2021 : à actualiser avant d’investir.
A37: • Catégories déduites des légendes (indicatif) ; 100 vidéos par fichier : les petits effectifs sont à confirmer.
A39: 6 · RECOMMANDATION FINALE : QUI CONTACTER ?
A40: Pour conclure, je réponds à la question de départ : qui contacter ?
A41: ="Si je ne devais en choisir qu’un, ce serait "&Contacts!B11&" : "&ROUND(Contacts!F11*100,0)&" % d’engagement, "&ROUND(Contacts!E11/1000000,0)&" millions de vues et "&Contacts!D11&" vidéos en tendance, la régularité la plus forte de ma liste." -> Si je ne devais en choisir qu’un, ce serait TND-010 : 25 % d’engagement, 74 millions de vues et 3 vidéos en tendance, la régularité la plus forte de ma liste.
A42: BTS engage davantage, mais c’est probablement une organisation, donc un partenariat différent.
A43: ="Et si le client préfère un petit compte, "&Contacts!B26&" : "&TEXT(Contacts!C26,"# ##0")&" abonnés pour "&ROUND(Contacts!E26/1000000,0)&" millions de vues." -> Et si le client préfère un petit compte, HSH-013 : 144 200 abonnés pour 46 millions de vues.
A44: Ce choix repose sur trois enseignements : la performance vient de la réaction du public, pas des réglages ; les niches engagent mieux que la portée brute ; l’audience n’achète pas l’engagement.

Sheet Succès
A1: Définir le succès : ce que mesurent les chiffres
A3: DÉFINITION RETENUE
A4: Une vidéo est un succès quand elle cumule deux choses : une PORTÉE (vues ≥ médiane du fichier) et un ENGAGEMENT (taux d’engagement ≥ médiane du fichier).
A5: Taux d’engagement = (J’aime + commentaires + partages) ÷ vues. Il mesure la réaction du public, indépendamment de la taille du compte ; les vues seules et les J’aime bruts favorisent mécaniquement les gros comptes. Médiane plutôt que moyenne : quelques vidéos virales faussent les moyennes.
A6: Un créateur est « à succès » quand son taux d’engagement cumulé (toutes ses vidéos) dépasse nettement la médiane ET que ses vues cumulées dépassent la médiane d’une vidéo.
A8: A. LES 4 FICHIERS EN UN COUP D’ŒIL (repères de réussite par fichier)
A9: Source | B9: Contenu du fichier | C9: Nb vidéos | D9: Vues médianes | E9: Taux d’engagement médian | F9: Part des J’aime dans les interactions | G9: Rôle dans l’analyse
A10: Tendance | B10: Vidéos en tendance (84 créateurs) | C10: =COUNT(Données!$L$2:$L$101) -> 100 | D10: =MEDIAN(Données!$L$2:$L$101) -> 10400000 | E10: =MEDIAN(Données!$P$2:$P$101) -> 0.10677181 | F10: =SUM(Données!$M$2:$M$101)/(SUM(Données!$M$2:$M$101)+SUM(Données!$N$2:$N$101)+SUM(Données!$O$2:$O$101)) -> 0.94364942 | G10: Fichier principal : seul à mélanger de nombreux créateurs
A11: Aimées | B11: Vidéos aimées par le compte @tiktok | C11: =COUNT(Données!$L$102:$L$201) -> 100 | D11: =MEDIAN(Données!$L$102:$L$201) -> 5700000 | E11: =MEDIAN(Données!$P$102:$P$201) -> 0.18322882 | F11: =SUM(Données!$M$102:$M$201)/(SUM(Données!$M$102:$M$201)+SUM(Données!$N$102:$N$201)+SUM(Données!$O$102:$O$201)) -> 0.96235483 | G11: Contrôle de robustesse (sélection éditoriale)
A12: Officiel | B12: Vidéos du compte officiel @tiktok | C12: =COUNT(Données!$L$202:$L$301) -> 100 | D12: =MEDIAN(Données!$L$202:$L$301) -> 3250000 | E12: =MEDIAN(Données!$P$202:$P$301) -> 0.066920952 | F12: =SUM(Données!$M$202:$M$301)/(SUM(Données!$M$202:$M$301)+SUM(Données!$N$202:$N$301)+SUM(Données!$O$202:$O$301)) -> 0.92175918 | G12: Repère « contenu de marque »
A13: Hashtag | B13: Vidéos du hashtag humour (79 créateurs) | C13: =COUNT(Données!$L$302:$L$401) -> 100 | D13: =MEDIAN(Données!$L$302:$L$401) -> 53650000 | E13: =MEDIAN(Données!$P$302:$P$401) -> 0.16348722 | F13: =SUM(Données!$M$302:$M$401)/(SUM(Données!$M$302:$M$401)+SUM(Données!$N$302:$N$401)+SUM(Données!$O$302:$O$401)) -> 0.96037227 | G13: Seul fichier avec le nombre d’abonnés
A15: B. POURQUOI DEUX MESURES ET PAS UNE (vidéos en tendance)
A16: Profil de la vidéo | B16: Règle | C16: Nb vidéos | D16: Part des vidéos | E16: Vues médianes | F16: Taux d’engagement médian | G16: Part des vues cumulées
A17: Succès complet | B17: Vues ≥ médiane ET engagement ≥ médiane | C17: =COUNTIF(Données!$S$2:$S$101,A17) -> 30 | D17: =C17/SUM($C$17:$C$20) -> 0.3 | E17: {=MEDIAN(IF(Données!$S$2:$S$101=A17,Données!$L$2:$L$101))} -> 25600000 | F17: {=MEDIAN(IF(Données!$S$2:$S$101=A17,Données!$P$2:$P$101))} -> 0.15584566 | G17: =SUMIF(Données!$S$2:$S$101,A17,Données!$L$2:$L$101)/SUM(Données!$L$2:$L$101) -> 0.58370973
A18: Engagé, portée modeste | B18: Engagement ≥ médiane, vues < médiane | C18: =COUNTIF(Données!$S$2:$S$101,A18) -> 20 | D18: =C18/SUM($C$17:$C$20) -> 0.2 | E18: {=MEDIAN(IF(Données!$S$2:$S$101=A18,Données!$L$2:$L$101))} -> 3850000 | F18: {=MEDIAN(IF(Données!$S$2:$S$101=A18,Données!$P$2:$P$101))} -> 0.15772828 | G18: =SUMIF(Données!$S$2:$S$101,A18,Données!$L$2:$L$101)/SUM(Données!$L$2:$L$101) -> 0.038965211
A19: Portée sans engagement | B19: Vues ≥ médiane, engagement < médiane | C19: =COUNTIF(Données!$S$2:$S$101,A19) -> 20 | D19: =C19/SUM($C$17:$C$20) -> 0.2 | E19: {=MEDIAN(IF(Données!$S$2:$S$101=A19,Données!$L$2:$L$101))} -> 29250000 | F19: {=MEDIAN(IF(Données!$S$2:$S$101=A19,Données!$P$2:$P$101))} -> 0.076537952 | G19: =SUMIF(Données!$S$2:$S$101,A19,Données!$L$2:$L$101)/SUM(Données!$L$2:$L$101) -> 0.33085437
A20: Standard | B20: Les deux sous la médiane | C20: =COUNTIF(Données!$S$2:$S$101,A20) -> 30 | D20: =C20/SUM($C$17:$C$20) -> 0.3 | E20: {=MEDIAN(IF(Données!$S$2:$S$101=A20,Données!$L$2:$L$101))} -> 3150000 | F20: {=MEDIAN(IF(Données!$S$2:$S$101=A20,Données!$P$2:$P$101))} -> 0.07523562 | G20: =SUMIF(Données!$S$2:$S$101,A20,Données!$L$2:$L$101)/SUM(Données!$L$2:$L$101) -> 0.046470692
A22: ="Lecture : si portée et engagement allaient ensemble, il n’y aurait que deux profils. Or "&C19&" vidéos ont de la portée sans engagement et "&C18&" l’inverse : les vues seules ne disent pas si le public réagit. Seules "&C17&" vidéos sur "&SUM(C17:C20)&" cumulent les deux." -> Lecture : si portée et engagement allaient ensemble, il n’y aurait que deux profils. Or 20 vidéos ont de la portée sans engagement et 20 l’inverse : les vues seules ne disent pas si le public réagit. Seules 30 vidéos sur 100 cumulent les deux.
A23: Repères entre fichiers : le taux d’engagement médian varie fortement selon la façon dont le fichier a été constitué (compte officiel vs sélections de contenus populaires). On compare donc toujours une vidéo à la médiane des on fichier, jamais d’un fichier à l’autre.

Sheet Facteurs
A1: Facteurs : ce qui distingue les vidéos à succès des autres
A2: Comparaison des médianes : vidéos « succès complet » vs les autres (100 vidéos en tendance). Corrélation ≠ causalité : on compare des contenus déjà populaires entre eux.
A4: A. LES VIDÉOS À SUCCÈS COMPLET VS LES AUTRES (vidéos en tendance / trending_videos)
A5: Facteur | B5: Succès complet (médiane) | C5: Autres vidéos (médiane) | D5: Rapport succès / autres | E5: Lecture
A6: Taux de J’aime (J’aime ÷ vues) | B6: {=MEDIAN(IF(Données!$T$2:$T$101=1,Données!$M$2:$M$101/Données!$L$2:$L$101))} -> 0.14571226 | C6: {=MEDIAN(IF(Données!$T$2:$T$101=0,Données!$M$2:$M$101/Données!$L$2:$L$101))} -> 0.076847328 | D6: =B6/C6 -> 1.8961265 | E6: Distingue nettement : le haut du panier est surtout une vidéo que le public aime.
A7: Taux de commentaires | B7: {=MEDIAN(IF(Données!$T$2:$T$101=1,Données!$N$2:$N$101/Données!$L$2:$L$101))} -> 0.0017876481 | C7: {=MEDIAN(IF(Données!$T$2:$T$101=0,Données!$N$2:$N$101/Données!$L$2:$L$101))} -> 0.00084208874 | D7: =B7/C7 -> 2.1228738 | E7: Distingue : ça discute plus.
A8: Taux de partages | B8: {=MEDIAN(IF(Données!$T$2:$T$101=1,Données!$O$2:$O$101/Données!$L$2:$L$101))} -> 0.0023732236 | C8: {=MEDIAN(IF(Données!$T$2:$T$101=0,Données!$O$2:$O$101/Données!$L$2:$L$101))} -> 0.006030722 | D8: =B8/C8 -> 0.39352231 | E8: Ne distingue pas : les partages sont même plus rares chez les vidéos à succès.
A9: Durée de la vidéo (s) | B9: {=MEDIAN(IF(Données!$T$2:$T$101=1,Données!$H$2:$H$101))} -> 12 | C9: {=MEDIAN(IF(Données!$T$2:$T$101=0,Données!$H$2:$H$101))} -> 11 | D9: =B9/C9 -> 1.0909091 | E9: Aucune différence : la durée n’explique pas le succès.
A10: Nombre de hashtags | B10: {=MEDIAN(IF(Données!$T$2:$T$101=1,Données!$I$2:$I$101))} -> 3 | C10: {=MEDIAN(IF(Données!$T$2:$T$101=0,Données!$I$2:$I$101))} -> 3 | D10: =B10/C10 -> 1 | E10: Aucune différence.
A11: Longueur de la légende (car.) | B11: {=MEDIAN(IF(Données!$T$2:$T$101=1,Données!$J$2:$J$101))} -> 49 | C11: {=MEDIAN(IF(Données!$T$2:$T$101=0,Données!$J$2:$J$101))} -> 46 | D11: =B11/C11 -> 1.0652174 | E11: Aucune différence.
A12: Part des vidéos avec un hashtag générique (#fyp, #foryou, #viral…) | B12: =AVERAGEIF(Données!$T$2:$T$101,1,Données!$K$2:$K$101) -> 0.26666667 | C12: =AVERAGEIF(Données!$T$2:$T$101,0,Données!$K$2:$K$101) -> 0.48571429 | D12: =B12/C12 -> 0.54901961 | E12: Les vidéos à succès en utilisent moins : ces hashtags ne sont pas un levier.
A13: {="Effectifs : "&SUM(Données!$T$2:$T$101)&" vidéos à succès complet contre "&(COUNT(Données!$T$2:$T$101)-SUM(Données!$T$2:$T$101))&" autres. Taux d’engagement médian : "&ROUND(MEDIAN(IF(Données!$T$2:$T$101=1,Données!$P$2:$P$101))*100,1)&" % contre "&ROUND(MEDIAN(IF(Données!$T$2:$T$101=0,Données!$P$2:$P$101))*100,1)&" %."} -> Effectifs : 30 vidéos à succès complet contre 70 autres. Taux d’engagement médian : 15,6 % contre 8,2 %.
A15: B. TAILLE D’AUDIENCE (fichier hashtag humour : seul fichier avec les abonnés)
A16: Palier d’audience | B16: Abonnés de | C16: Abonnés jusqu’à (exclu) | D16: Nb vidéos | E16: Taux d’engagement médian | F16: Vues médianes | G16: Vues par abonné (médiane)
A17: Moins de 1 M d’abonnés | B17: 0 | C17: 1000000 | D17: =SUMPRODUCT((Données!$G$302:$G$401>=B17)*(Données!$G$302:$G$401<C17)) -> 28 | E17: {=MEDIAN(IF((Données!$G$302:$G$401>=B17)*(Données!$G$302:$G$401<C17)=1,Données!$P$302:$P$401))} -> 0.19109258 | F17: {=MEDIAN(IF((Données!$G$302:$G$401>=B17)*(Données!$G$302:$G$401<C17)=1,Données!$L$302:$L$401))} -> 48400000 | G17: {=MEDIAN(IF((Données!$G$302:$G$401>=B17)*(Données!$G$302:$G$401<C17)=1,Données!$R$302:$R$401))} -> 111.79581
A18: 1 à 5 M d’abonnés | B18: 1000000 | C18: 5000000 | D18: =SUMPRODUCT((Données!$G$302:$G$401>=B18)*(Données!$G$302:$G$401<C18)) -> 35 | E18: {=MEDIAN(IF((Données!$G$302:$G$401>=B18)*(Données!$G$302:$G$401<C18)=1,Données!$P$302:$P$401))} -> 0.14329602 | F18: {=MEDIAN(IF((Données!$G$302:$G$401>=B18)*(Données!$G$302:$G$401<C18)=1,Données!$L$302:$L$401))} -> 65900000 | G18: {=MEDIAN(IF((Données!$G$302:$G$401>=B18)*(Données!$G$302:$G$401<C18)=1,Données!$R$302:$R$401))} -> 29.714286
A19: Plus de 5 M d’abonnés | B19: 5000000 | C19: 10000000000 | D19: =SUMPRODUCT((Données!$G$302:$G$401>=B19)*(Données!$G$302:$G$401<C19)) -> 37 | E19: {=MEDIAN(IF((Données!$G$302:$G$401>=B19)*(Données!$G$302:$G$401<C19)=1,Données!$P$302:$P$401))} -> 0.15439209 | F19: {=MEDIAN(IF((Données!$G$302:$G$401>=B19)*(Données!$G$302:$G$401<C19)=1,Données!$L$302:$L$401))} -> 55400000 | G19: {=MEDIAN(IF((Données!$G$302:$G$401>=B19)*(Données!$G$302:$G$401<C19)=1,Données!$R$302:$R$401))} -> 6.278481
A20: Compte vérifié | B20: — | C20: — | D20: =COUNTIF(Données!$F$302:$F$401,"Oui") -> 41 | E20: {=MEDIAN(IF(Données!$F$302:$F$401="Oui",Données!$P$302:$P$401))} -> 0.15439209 | F20: {=MEDIAN(IF(Données!$F$302:$F$401="Oui",Données!$L$302:$L$401))} -> 54200000 | G20: {=MEDIAN(IF(Données!$F$302:$F$401="Oui",Données!$R$302:$R$401))} -> 7.6
A21: Compte non vérifié | B21: — | C21: — | D21: =COUNTIF(Données!$F$302:$F$401,"Non") -> 59 | E21: {=MEDIAN(IF(Données!$F$302:$F$401="Non",Données!$P$302:$P$401))} -> 0.16800606 | F21: {=MEDIAN(IF(Données!$F$302:$F$401="Non",Données!$L$302:$L$401))} -> 52600000 | G21: {=MEDIAN(IF(Données!$F$302:$F$401="Non",Données!$R$302:$R$401))} -> 70.327553
A22: Lecture : les plus petits comptes engagent le plus et obtiennent des vues par abonné sans commune mesure ; le badge « vérifié » n’apporte pas d’engagement supplémentaire. L’audience n’est donc ni nécessaire ni suffisante.
A24: C. LE CONSTAT TIENT-IL DANS LES AUTRES FICHIERS ? (médianes, succès complet vs autres)
A25: Fichier | B25: Taux de J’aime : succès | C25: Taux de J’aime : autres | D25: Durée (s) : succès | E25: Durée (s) : autres | F25: Nb hashtags : succès | G25: Nb hashtags : autres
A26: Aimées | B26: {=MEDIAN(IF(Données!$T$102:$T$201=1,Données!$Q$102:$Q$201))} -> 0.22727273 | C26: {=MEDIAN(IF(Données!$T$102:$T$201=0,Données!$Q$102:$Q$201))} -> 0.14820042 | D26: {=MEDIAN(IF(Données!$T$102:$T$201=1,Données!$H$102:$H$201))} -> 15 | E26: {=MEDIAN(IF(Données!$T$102:$T$201=0,Données!$H$102:$H$201))} -> 16 | F26: {=MEDIAN(IF(Données!$T$102:$T$201=1,Données!$I$102:$I$201))} -> 1 | G26: {=MEDIAN(IF(Données!$T$102:$T$201=0,Données!$I$102:$I$201))} -> 2
A27: Officiel | B27: {=MEDIAN(IF(Données!$T$202:$T$301=1,Données!$Q$202:$Q$301))} -> 0.083898026 | C27: {=MEDIAN(IF(Données!$T$202:$T$301=0,Données!$Q$202:$Q$301))} -> 0.047333976 | D27: {=MEDIAN(IF(Données!$T$202:$T$301=1,Données!$H$202:$H$301))} -> 30 | E27: {=MEDIAN(IF(Données!$T$202:$T$301=0,Données!$H$202:$H$301))} -> 21.5 | F27: {=MEDIAN(IF(Données!$T$202:$T$301=1,Données!$I$202:$I$301))} -> 1 | G27: {=MEDIAN(IF(Données!$T$202:$T$301=0,Données!$I$202:$I$301))} -> 1
A28: Hashtag | B28: {=MEDIAN(IF(Données!$T$302:$T$401=1,Données!$Q$302:$Q$401))} -> 0.18011324 | C28: {=MEDIAN(IF(Données!$T$302:$T$401=0,Données!$Q$302:$Q$401))} -> 0.14496321 | D28: {=MEDIAN(IF(Données!$T$302:$T$401=1,Données!$H$302:$H$401))} -> 12 | E28: {=MEDIAN(IF(Données!$T$302:$T$401=0,Données!$H$302:$H$401))} -> 17.5 | F28: {=MEDIAN(IF(Données!$T$302:$T$401=1,Données!$I$302:$I$401))} -> 7 | G28: {=MEDIAN(IF(Données!$T$302:$T$401=0,Données!$I$302:$I$401))} -> 8.5
A29: Lecture : dans les trois autres fichiers, le taux de J’aime reste le seul facteur qui sépare nettement les succès du reste ; durée et hashtags ne montrent pas d’écart constant d’un fichier à l’autre. Seuls des tests contrôlés permettraient de parler de levier.

Sheet Catégories
A1: Catégories : qui domine, et pourquoi
A2: Catégories = thème de CHAQUE créateur, déduit par mots-clés des légendes et hashtags du fichier (aucune donnée externe). Un créateur sans mot-clé exploitable est « Non classé ». Source : 100 vidéos en tendance.
A4: A. PERFORMANCE PAR CATÉGORIE | N4: Données triées pour les graphiques (calculées)
A5: Catégorie | B5: Nb vidéos | C5: Nb créateurs | D5: Vues cumulées | E5: Part des vues | F5: Taux d’engagement médian | G5: % de vidéos « succès complet » | H5: Créateur dominant (portée) | I5: Sa part des vues de la catégorie | J5: Créateur le plus engageant* | K5: Son taux d’engagement | L5: Lecture | N5: Catégorie | O5: Taux d’engagement médian | P5: Catégorie | Q5: Part des vues
A6: Humour & sketchs | B6: =COUNTIF(Données!$E$2:$E$101,A6) -> 18 | C6: =SUMPRODUCT((Données!$E$2:$E$101=A6)/COUNTIFS(Données!$C$2:$C$101,Données!$C$2:$C$101,Données!$E$2:$E$101,Données!$E$2:$E$101)) -> 17 | D6: =SUMIF(Données!$E$2:$E$101,A6,Données!$L$2:$L$101) -> 604437500 | E6: =D6/SUM($D$6:$D$11) -> 0.2584733 | F6: {=MEDIAN(IF(Données!$E$2:$E$101=A6,Données!$P$2:$P$101))} -> 0.078600357 | G6: =COUNTIFS(Données!$E$2:$E$101,A6,Données!$S$2:$S$101,"Succès complet")/B6 -> 0.27777778 | H6: Compte TND-049 | I6: =SUMIF(Données!$C$2:$C$101,"TND-049",Données!$L$2:$L$101)/D6 -> 0.27347741 | J6: Compte TND-060 | K6: =(SUMIF(Données!$C$2:$C$101,"TND-060",Données!$M$2:$M$101)+SUMIF(Données!$C$2:$C$101,"TND-060",Données!$N$2:$N$101)+SUMIF(Données!$C$2:$C$101,"TND-060",Données!$O$2:$O$101))/SUMIF(Données!$C$2:$C$101,"TND-060",Données!$L$2:$L$101) -> 0.14754811 | L6: Domine par la portée (plus grosse part des vues identifiées) mais engagement le plus faible : on regarde beaucoup, on réagit peu. | N6: =INDEX($A$6:$A$11,MATCH(O6,$F$6:$F$11,0)) -> Humour & sketchs | O6: =SMALL($F$6:$F$11,1) -> 0.078600357 | P6: =INDEX($A$6:$A$11,MATCH(Q6,$E$6:$E$11,0)) -> Musique & danse | Q6: =SMALL($E$6:$E$11,1) -> 0.04280538
A7: Animaux | B7: =COUNTIF(Données!$E$2:$E$101,A7) -> 17 | C7: =SUMPRODUCT((Données!$E$2:$E$101=A7)/COUNTIFS(Données!$C$2:$C$101,Données!$C$2:$C$101,Données!$E$2:$E$101,Données!$E$2:$E$101)) -> 17 | D7: =SUMIF(Données!$E$2:$E$101,A7,Données!$L$2:$L$101) -> 151191300 | E7: =D7/SUM($D$6:$D$11) -> 0.064653357 | F7: {=MEDIAN(IF(Données!$E$2:$E$101=A7,Données!$P$2:$P$101))} -> 0.1017943 | G7: =COUNTIFS(Données!$E$2:$E$101,A7,Données!$S$2:$S$101,"Succès complet")/B7 -> 0.11764706 | H7: Compte TND-003 | I7: =SUMIF(Données!$C$2:$C$101,"TND-003",Données!$L$2:$L$101)/D7 -> 0.29829759 | J7: TND-014 | K7: =(SUMIF(Données!$C$2:$C$101,"TND-014",Données!$M$2:$M$101)+SUMIF(Données!$C$2:$C$101,"TND-014",Données!$N$2:$N$101)+SUMIF(Données!$C$2:$C$101,"TND-014",Données!$O$2:$O$101))/SUMIF(Données!$C$2:$C$101,"TND-014",Données!$L$2:$L$101) -> 0.19607895 | L7: Portée médiane modeste et engagement moyen : terrain accessible mais rarement un succès complet. | N7: =INDEX($A$6:$A$11,MATCH(O7,$F$6:$F$11,0)) -> Non classé | O7: =SMALL($F$6:$F$11,2) -> 0.098003125 | P7: =INDEX($A$6:$A$11,MATCH(Q7,$E$6:$E$11,0)) -> Food & lifestyle | Q7: =SMALL($E$6:$E$11,2) -> 0.05276907
A8: Famille & enfants | B8: =COUNTIF(Données!$E$2:$E$101,A8) -> 14 | C8: =SUMPRODUCT((Données!$E$2:$E$101=A8)/COUNTIFS(Données!$C$2:$C$101,Données!$C$2:$C$101,Données!$E$2:$E$101,Données!$E$2:$E$101)) -> 14 | D8: =SUMIF(Données!$E$2:$E$101,A8,Données!$L$2:$L$101) -> 284500000 | E8: =D8/SUM($D$6:$D$11) -> 0.12165965 | F8: {=MEDIAN(IF(Données!$E$2:$E$101=A8,Données!$P$2:$P$101))} -> 0.13478348 | G8: =COUNTIFS(Données!$E$2:$E$101,A8,Données!$S$2:$S$101,"Succès complet")/B8 -> 0.28571429 | H8: Compte TND-008 | I8: =SUMIF(Données!$C$2:$C$101,"TND-008",Données!$L$2:$L$101)/D8 -> 0.28049209 | J8: TND-052 | K8: =(SUMIF(Données!$C$2:$C$101,"TND-052",Données!$M$2:$M$101)+SUMIF(Données!$C$2:$C$101,"TND-052",Données!$N$2:$N$101)+SUMIF(Données!$C$2:$C$101,"TND-052",Données!$O$2:$O$101))/SUMIF(Données!$C$2:$C$101,"TND-052",Données!$L$2:$L$101) -> 0.17048358 | L8: Engagement au-dessus de la médiane avec une bonne portée : bon équilibre entre vues et réaction. | N8: =INDEX($A$6:$A$11,MATCH(O8,$F$6:$F$11,0)) -> Animaux | O8: =SMALL($F$6:$F$11,3) -> 0.1017943 | P8: =INDEX($A$6:$A$11,MATCH(Q8,$E$6:$E$11,0)) -> Animaux | Q8: =SMALL($E$6:$E$11,3) -> 0.064653357
A9: Food & lifestyle | B9: =COUNTIF(Données!$E$2:$E$101,A9) -> 7 | C9: =SUMPRODUCT((Données!$E$2:$E$101=A9)/COUNTIFS(Données!$C$2:$C$101,Données!$C$2:$C$101,Données!$E$2:$E$101,Données!$E$2:$E$101)) -> 5 | D9: =SUMIF(Données!$E$2:$E$101,A9,Données!$L$2:$L$101) -> 123400000 | E9: =D9/SUM($D$6:$D$11) -> 0.05276907 | F9: {=MEDIAN(IF(Données!$E$2:$E$101=A9,Données!$P$2:$P$101))} -> 0.16186747 | G9: =COUNTIFS(Données!$E$2:$E$101,A9,Données!$S$2:$S$101,"Succès complet")/B9 -> 0.71428571 | H9: TND-010 | I9: =SUMIF(Données!$C$2:$C$101,"TND-010",Données!$L$2:$L$101)/D9 -> 0.59886548 | J9: TND-010 | K9: =(SUMIF(Données!$C$2:$C$101,"TND-010",Données!$M$2:$M$101)+SUMIF(Données!$C$2:$C$101,"TND-010",Données!$N$2:$N$101)+SUMIF(Données!$C$2:$C$101,"TND-010",Données!$O$2:$O$101))/SUMIF(Données!$C$2:$C$101,"TND-010",Données!$L$2:$L$101) -> 0.25065765 | L9: Meilleur engagement médian, 5 vidéos sur 7 en succès complet ; mais 7 vidéos seulement et un seul créateur pèse plus de la moitié des vues : signal à confirmer. | N9: =INDEX($A$6:$A$11,MATCH(O9,$F$6:$F$11,0)) -> Musique & danse | O9: =SMALL($F$6:$F$11,4) -> 0.11304522 | P9: =INDEX($A$6:$A$11,MATCH(Q9,$E$6:$E$11,0)) -> Famille & enfants | Q9: =SMALL($E$6:$E$11,4) -> 0.12165965
A10: Musique & danse | B10: =COUNTIF(Données!$E$2:$E$101,A10) -> 5 | C10: =SUMPRODUCT((Données!$E$2:$E$101=A10)/COUNTIFS(Données!$C$2:$C$101,Données!$C$2:$C$101,Données!$E$2:$E$101,Données!$E$2:$E$101)) -> 4 | D10: =SUMIF(Données!$E$2:$E$101,A10,Données!$L$2:$L$101) -> 100100000 | E10: =D10/SUM($D$6:$D$11) -> 0.04280538 | F10: {=MEDIAN(IF(Données!$E$2:$E$101=A10,Données!$P$2:$P$101))} -> 0.11304522 | G10: =COUNTIFS(Données!$E$2:$E$101,A10,Données!$S$2:$S$101,"Succès complet")/B10 -> 0.4 | H10: Compte TND-042 | I10: =SUMIF(Données!$C$2:$C$101,"TND-042",Données!$L$2:$L$101)/D10 -> 0.43156843 | J10: @bts_official_bighit | K10: =(SUMIF(Données!$C$2:$C$101,"TND-001",Données!$M$2:$M$101)+SUMIF(Données!$C$2:$C$101,"TND-001",Données!$N$2:$N$101)+SUMIF(Données!$C$2:$C$101,"TND-001",Données!$O$2:$O$101))/SUMIF(Données!$C$2:$C$101,"TND-001",Données!$L$2:$L$101) -> 0.3609176 | L10: Seulement 5 vidéos : non concluant. | N10: =INDEX($A$6:$A$11,MATCH(O10,$F$6:$F$11,0)) -> Famille & enfants | O10: =SMALL($F$6:$F$11,5) -> 0.13478348 | P10: =INDEX($A$6:$A$11,MATCH(Q10,$E$6:$E$11,0)) -> Humour & sketchs | Q10: =SMALL($E$6:$E$11,5) -> 0.2584733
A11: Non classé | B11: =COUNTIF(Données!$E$2:$E$101,A11) -> 39 | C11: =SUMPRODUCT((Données!$E$2:$E$101=A11)/COUNTIFS(Données!$C$2:$C$101,Données!$C$2:$C$101,Données!$E$2:$E$101,Données!$E$2:$E$101)) -> 27 | D11: =SUMIF(Données!$E$2:$E$101,A11,Données!$L$2:$L$101) -> 1074862300 | E11: =D11/SUM($D$6:$D$11) -> 0.45963925 | F11: {=MEDIAN(IF(Données!$E$2:$E$101=A11,Données!$P$2:$P$101))} -> 0.098003125 | G11: =COUNTIFS(Données!$E$2:$E$101,A11,Données!$S$2:$S$101,"Succès complet")/B11 -> 0.30769231 | H11: Compte TND-051 | I11: =SUMIF(Données!$C$2:$C$101,"TND-051",Données!$L$2:$L$101)/D11 -> 0.20681719 | J11: TND-039 | K11: =(SUMIF(Données!$C$2:$C$101,"TND-039",Données!$M$2:$M$101)+SUMIF(Données!$C$2:$C$101,"TND-039",Données!$N$2:$N$101)+SUMIF(Données!$C$2:$C$101,"TND-039",Données!$O$2:$O$101))/SUMIF(Données!$C$2:$C$101,"TND-039",Données!$L$2:$L$101) -> 0.23800709 | L11: Légende vide ou sans mot-clé : 39 % des vidéos et la plus grosse portée (comptes très suivis), mais thème inconnu. | N11: =INDEX($A$6:$A$11,MATCH(O11,$F$6:$F$11,0)) -> Food & lifestyle | O11: =SMALL($F$6:$F$11,6) -> 0.16186747 | P11: =INDEX($A$6:$A$11,MATCH(Q11,$E$6:$E$11,0)) -> Non classé | Q11: =SMALL($E$6:$E$11,6) -> 0.45963925
A12: Total / médiane | B12: =SUM(B6:B11) -> 100 | C12: =SUMPRODUCT(1/COUNTIF(Données!$C$2:$C$101,Données!$C$2:$C$101)) -> 84 | D12: =SUM(D6:D11) -> 2338491100 | E12: =SUM(E6:E11) -> 1 | F12: =MEDIAN(Données!$P$2:$P$101) -> 0.10677181 | G12: =COUNTIF(Données!$S$2:$S$101,"Succès complet")/B12 -> 0.3
A13: * Parmi les créateurs de la catégorie dont les vues cumulées dépassent la médiane d’une vidéo (évite de distinguer un créateur sur une seule petite vidéo). Les créateurs non retenus pour le contact sont désignés par une référence anonyme (TND-xxx).
A31: B. DÉTAIL DU TREEMAP : créateurs (taille = vues cumulées, couleur = catégorie)
A32: Catégorie (couleur) | B32: N° | C32: Réf. interne | D32: Vues cumulées (taille) | E32: Interactions | F32: Taux d’engagement | G32: Part des vues totales | H32: Créateur
A33: Humour & sketchs | B33: 1 | C33: TND-049 | D33: =SUMIF(Données!$C$2:$C$101,C33,Données!$L$2:$L$101) -> 165300000 | E33: =SUMIF(Données!$C$2:$C$101,C33,Données!$M$2:$M$101)+SUMIF(Données!$C$2:$C$101,C33,Données!$N$2:$N$101)+SUMIF(Données!$C$2:$C$101,C33,Données!$O$2:$O$101) -> 17826934 | F33: =E33/D33 -> 0.10784594 | G33: =D33/SUM(Données!$L$2:$L$101) -> 0.070686606 | H33: Compte TND-049
A34: Humour & sketchs | B34: 2 | C34: TND-060 | D34: =SUMIF(Données!$C$2:$C$101,C34,Données!$L$2:$L$101) -> 106000000 | E34: =SUMIF(Données!$C$2:$C$101,C34,Données!$M$2:$M$101)+SUMIF(Données!$C$2:$C$101,C34,Données!$N$2:$N$101)+SUMIF(Données!$C$2:$C$101,C34,Données!$O$2:$O$101) -> 15640100 | F34: =E34/D34 -> 0.14754811 | G34: =D34/SUM(Données!$L$2:$L$101) -> 0.045328374 | H34: Compte TND-060
A35: Humour & sketchs | B35: 3 | C35: TND-004 | D35: =SUMIF(Données!$C$2:$C$101,C35,Données!$L$2:$L$101) -> 101200000 | E35: =SUMIF(Données!$C$2:$C$101,C35,Données!$M$2:$M$101)+SUMIF(Données!$C$2:$C$101,C35,Données!$N$2:$N$101)+SUMIF(Données!$C$2:$C$101,C35,Données!$O$2:$O$101) -> 12333300 | F35: =E35/D35 -> 0.12187055 | G35: =D35/SUM(Données!$L$2:$L$101) -> 0.043275769 | H35: Compte TND-004
A36: Humour & sketchs | B36: 4 | C36: TND-057 | D36: =SUMIF(Données!$C$2:$C$101,C36,Données!$L$2:$L$101) -> 84500000 | E36: =SUMIF(Données!$C$2:$C$101,C36,Données!$M$2:$M$101)+SUMIF(Données!$C$2:$C$101,C36,Données!$N$2:$N$101)+SUMIF(Données!$C$2:$C$101,C36,Données!$O$2:$O$101) -> 12181900 | F36: =E36/D36 -> 0.1441645 | G36: =D36/SUM(Données!$L$2:$L$101) -> 0.036134412 | H36: Compte TND-057
A37: Humour & sketchs | B37: 5 | C37: — | D37: =SUMIF(Données!$E$2:$E$101,A37,Données!$L$2:$L$101)-D33-D34-D35-D36 -> 147437500 | E37: =SUMIF(Données!$E$2:$E$101,A37,Données!$M$2:$M$101)+SUMIF(Données!$E$2:$E$101,A37,Données!$N$2:$N$101)+SUMIF(Données!$E$2:$E$101,A37,Données!$O$2:$O$101)-E33-E34-E35-E36 -> 11962166 | F37: =E37/D37 -> 0.081133809 | G37: =D37/SUM(Données!$L$2:$L$101) -> 0.063048134 | H37: Autres (13 créateurs)
A38: Animaux | B38: 6 | C38: TND-003 | D38: =SUMIF(Données!$C$2:$C$101,C38,Données!$L$2:$L$101) -> 45100000 | E38: =SUMIF(Données!$C$2:$C$101,C38,Données!$M$2:$M$101)+SUMIF(Données!$C$2:$C$101,C38,Données!$N$2:$N$101)+SUMIF(Données!$C$2:$C$101,C38,Données!$O$2:$O$101) -> 4429000 | F38: =E38/D38 -> 0.098203991 | G38: =D38/SUM(Données!$L$2:$L$101) -> 0.01928594 | H38: Compte TND-003
A39: Animaux | B39: 7 | C39: TND-037 | D39: =SUMIF(Données!$C$2:$C$101,C39,Données!$L$2:$L$101) -> 13200000 | E39: =SUMIF(Données!$C$2:$C$101,C39,Données!$M$2:$M$101)+SUMIF(Données!$C$2:$C$101,C39,Données!$N$2:$N$101)+SUMIF(Données!$C$2:$C$101,C39,Données!$O$2:$O$101) -> 2368300 | F39: =E39/D39 -> 0.17941667 | G39: =D39/SUM(Données!$L$2:$L$101) -> 0.0056446655 | H39: TND-037
A40: Animaux | B40: 8 | C40: TND-014 | D40: =SUMIF(Données!$C$2:$C$101,C40,Données!$L$2:$L$101) -> 11400000 | E40: =SUMIF(Données!$C$2:$C$101,C40,Données!$M$2:$M$101)+SUMIF(Données!$C$2:$C$101,C40,Données!$N$2:$N$101)+SUMIF(Données!$C$2:$C$101,C40,Données!$O$2:$O$101) -> 2235300 | F40: =E40/D40 -> 0.19607895 | G40: =D40/SUM(Données!$L$2:$L$101) -> 0.0048749384 | H40: TND-014
A41: Animaux | B41: 9 | C41: — | D41: =SUMIF(Données!$E$2:$E$101,A41,Données!$L$2:$L$101)-D38-D39-D40 -> 81491300 | E41: =SUMIF(Données!$E$2:$E$101,A41,Données!$M$2:$M$101)+SUMIF(Données!$E$2:$E$101,A41,Données!$N$2:$N$101)+SUMIF(Données!$E$2:$E$101,A41,Données!$O$2:$O$101)-E38-E39-E40 -> 8741855 | F41: =E41/D41 -> 0.10727348 | G41: =D41/SUM(Données!$L$2:$L$101) -> 0.034847813 | H41: Autres (14 créateurs)
A42: Famille & enfants | B42: 10 | C42: TND-008 | D42: =SUMIF(Données!$C$2:$C$101,C42,Données!$L$2:$L$101) -> 79800000 | E42: =SUMIF(Données!$C$2:$C$101,C42,Données!$M$2:$M$101)+SUMIF(Données!$C$2:$C$101,C42,Données!$N$2:$N$101)+SUMIF(Données!$C$2:$C$101,C42,Données!$O$2:$O$101) -> 6120800 | F42: =E42/D42 -> 0.076701754 | G42: =D42/SUM(Données!$L$2:$L$101) -> 0.034124569 | H42: Compte TND-008
A43: Famille & enfants | B43: 11 | C43: TND-033 | D43: =SUMIF(Données!$C$2:$C$101,C43,Données!$L$2:$L$101) -> 56300000 | E43: =SUMIF(Données!$C$2:$C$101,C43,Données!$M$2:$M$101)+SUMIF(Données!$C$2:$C$101,C43,Données!$N$2:$N$101)+SUMIF(Données!$C$2:$C$101,C43,Données!$O$2:$O$101) -> 8766600 | F43: =E43/D43 -> 0.15571226 | G43: =D43/SUM(Données!$L$2:$L$101) -> 0.024075354 | H43: Compte TND-033
A44: Famille & enfants | B44: 12 | C44: TND-052 | D44: =SUMIF(Données!$C$2:$C$101,C44,Données!$L$2:$L$101) -> 33500000 | E44: =SUMIF(Données!$C$2:$C$101,C44,Données!$M$2:$M$101)+SUMIF(Données!$C$2:$C$101,C44,Données!$N$2:$N$101)+SUMIF(Données!$C$2:$C$101,C44,Données!$O$2:$O$101) -> 5711200 | F44: =E44/D44 -> 0.17048358 | G44: =D44/SUM(Données!$L$2:$L$101) -> 0.014325477 | H44: TND-052
A45: Famille & enfants | B45: 13 | C45: TND-023 | D45: =SUMIF(Données!$C$2:$C$101,C45,Données!$L$2:$L$101) -> 32200000 | E45: =SUMIF(Données!$C$2:$C$101,C45,Données!$M$2:$M$101)+SUMIF(Données!$C$2:$C$101,C45,Données!$N$2:$N$101)+SUMIF(Données!$C$2:$C$101,C45,Données!$O$2:$O$101) -> 5308300 | F45: =E45/D45 -> 0.16485404 | G45: =D45/SUM(Données!$L$2:$L$101) -> 0.013769563 | H45: TND-023
A46: Famille & enfants | B46: 14 | C46: TND-030 | D46: =SUMIF(Données!$C$2:$C$101,C46,Données!$L$2:$L$101) -> 25000000 | E46: =SUMIF(Données!$C$2:$C$101,C46,Données!$M$2:$M$101)+SUMIF(Données!$C$2:$C$101,C46,Données!$N$2:$N$101)+SUMIF(Données!$C$2:$C$101,C46,Données!$O$2:$O$101) -> 4154400 | F46: =E46/D46 -> 0.166176 | G46: =D46/SUM(Données!$L$2:$L$101) -> 0.010690654 | H46: TND-030
A47: Famille & enfants | B47: 15 | C47: — | D47: =SUMIF(Données!$E$2:$E$101,A47,Données!$L$2:$L$101)-D42-D43-D44-D45-D46 -> 57700000 | E47: =SUMIF(Données!$E$2:$E$101,A47,Données!$M$2:$M$101)+SUMIF(Données!$E$2:$E$101,A47,Données!$N$2:$N$101)+SUMIF(Données!$E$2:$E$101,A47,Données!$O$2:$O$101)-E42-E43-E44-E45-E46 -> 6180773 | F47: =E47/D47 -> 0.10711912 | G47: =D47/SUM(Données!$L$2:$L$101) -> 0.02467403 | H47: Autres (9 créateurs)
A48: Food & lifestyle | B48: 16 | C48: TND-010 | D48: =SUMIF(Données!$C$2:$C$101,C48,Données!$L$2:$L$101) -> 73900000 | E48: =SUMIF(Données!$C$2:$C$101,C48,Données!$M$2:$M$101)+SUMIF(Données!$C$2:$C$101,C48,Données!$N$2:$N$101)+SUMIF(Données!$C$2:$C$101,C48,Données!$O$2:$O$101) -> 18523600 | F48: =E48/D48 -> 0.25065765 | G48: =D48/SUM(Données!$L$2:$L$101) -> 0.031601574 | H48: TND-010
A49: Food & lifestyle | B49: 17 | C49: TND-067 | D49: =SUMIF(Données!$C$2:$C$101,C49,Données!$L$2:$L$101) -> 24900000 | E49: =SUMIF(Données!$C$2:$C$101,C49,Données!$M$2:$M$101)+SUMIF(Données!$C$2:$C$101,C49,Données!$N$2:$N$101)+SUMIF(Données!$C$2:$C$101,C49,Données!$O$2:$O$101) -> 4030500 | F49: =E49/D49 -> 0.16186747 | G49: =D49/SUM(Données!$L$2:$L$101) -> 0.010647892 | H49: TND-067
A50: Food & lifestyle | B50: 18 | C50: — | D50: =SUMIF(Données!$E$2:$E$101,A50,Données!$L$2:$L$101)-D48-D49 -> 24600000 | E50: =SUMIF(Données!$E$2:$E$101,A50,Données!$M$2:$M$101)+SUMIF(Données!$E$2:$E$101,A50,Données!$N$2:$N$101)+SUMIF(Données!$E$2:$E$101,A50,Données!$O$2:$O$101)-E48-E49 -> 2938324 | F50: =E50/D50 -> 0.11944407 | G50: =D50/SUM(Données!$L$2:$L$101) -> 0.010519604 | H50: Autres (3 créateurs)
A51: Musique & danse | B51: 19 | C51: TND-042 | D51: =SUMIF(Données!$C$2:$C$101,C51,Données!$L$2:$L$101) -> 43200000 | E51: =SUMIF(Données!$C$2:$C$101,C51,Données!$M$2:$M$101)+SUMIF(Données!$C$2:$C$101,C51,Données!$N$2:$N$101)+SUMIF(Données!$C$2:$C$101,C51,Données!$O$2:$O$101) -> 4771300 | F51: =E51/D51 -> 0.11044676 | G51: =D51/SUM(Données!$L$2:$L$101) -> 0.018473451 | H51: Compte TND-042
A52: Musique & danse | B52: 20 | C52: TND-001 | D52: =SUMIF(Données!$C$2:$C$101,C52,Données!$L$2:$L$101) -> 26700000 | E52: =SUMIF(Données!$C$2:$C$101,C52,Données!$M$2:$M$101)+SUMIF(Données!$C$2:$C$101,C52,Données!$N$2:$N$101)+SUMIF(Données!$C$2:$C$101,C52,Données!$O$2:$O$101) -> 9636500 | F52: =E52/D52 -> 0.3609176 | G52: =D52/SUM(Données!$L$2:$L$101) -> 0.011417619 | H52: @bts_official_bighit
A53: Musique & danse | B53: 21 | C53: — | D53: =SUMIF(Données!$E$2:$E$101,A53,Données!$L$2:$L$101)-D51-D52 -> 30200000 | E53: =SUMIF(Données!$E$2:$E$101,A53,Données!$M$2:$M$101)+SUMIF(Données!$E$2:$E$101,A53,Données!$N$2:$N$101)+SUMIF(Données!$E$2:$E$101,A53,Données!$O$2:$O$101)-E51-E52 -> 3038004 | F53: =E53/D53 -> 0.10059616 | G53: =D53/SUM(Données!$L$2:$L$101) -> 0.01291431 | H53: Autres (2 créateurs)
A54: Non classé | B54: 22 | C54: TND-051 | D54: =SUMIF(Données!$C$2:$C$101,C54,Données!$L$2:$L$101) -> 222300000 | E54: =SUMIF(Données!$C$2:$C$101,C54,Données!$M$2:$M$101)+SUMIF(Données!$C$2:$C$101,C54,Données!$N$2:$N$101)+SUMIF(Données!$C$2:$C$101,C54,Données!$O$2:$O$101) -> 31600000 | F54: =E54/D54 -> 0.14215025 | G54: =D54/SUM(Données!$L$2:$L$101) -> 0.095061298 | H54: Compte TND-051
A55: Non classé | B55: 23 | C55: TND-073 | D55: =SUMIF(Données!$C$2:$C$101,C55,Données!$L$2:$L$101) -> 200200000 | E55: =SUMIF(Données!$C$2:$C$101,C55,Données!$M$2:$M$101)+SUMIF(Données!$C$2:$C$101,C55,Données!$N$2:$N$101)+SUMIF(Données!$C$2:$C$101,C55,Données!$O$2:$O$101) -> 6298400 | F55: =E55/D55 -> 0.031460539 | G55: =D55/SUM(Données!$L$2:$L$101) -> 0.08561076 | H55: Compte TND-073
A56: Non classé | B56: 24 | C56: TND-028 | D56: =SUMIF(Données!$C$2:$C$101,C56,Données!$L$2:$L$101) -> 141219800 | E56: =SUMIF(Données!$C$2:$C$101,C56,Données!$M$2:$M$101)+SUMIF(Données!$C$2:$C$101,C56,Données!$N$2:$N$101)+SUMIF(Données!$C$2:$C$101,C56,Données!$O$2:$O$101) -> 14414366 | F56: =E56/D56 -> 0.10207043 | G56: =D56/SUM(Données!$L$2:$L$101) -> 0.060389283 | H56: Compte TND-028
A57: Non classé | B57: 25 | C57: TND-013 | D57: =SUMIF(Données!$C$2:$C$101,C57,Données!$L$2:$L$101) -> 109300000 | E57: =SUMIF(Données!$C$2:$C$101,C57,Données!$M$2:$M$101)+SUMIF(Données!$C$2:$C$101,C57,Données!$N$2:$N$101)+SUMIF(Données!$C$2:$C$101,C57,Données!$O$2:$O$101) -> 13120745 | F57: =E57/D57 -> 0.12004341 | G57: =D57/SUM(Données!$L$2:$L$101) -> 0.046739541 | H57: Compte TND-013
A58: Non classé | B58: 26 | C58: TND-053 | D58: =SUMIF(Données!$C$2:$C$101,C58,Données!$L$2:$L$101) -> 54300000 | E58: =SUMIF(Données!$C$2:$C$101,C58,Données!$M$2:$M$101)+SUMIF(Données!$C$2:$C$101,C58,Données!$N$2:$N$101)+SUMIF(Données!$C$2:$C$101,C58,Données!$O$2:$O$101) -> 4235100 | F58: =E58/D58 -> 0.077994475 | G58: =D58/SUM(Données!$L$2:$L$101) -> 0.023220101 | H58: Compte TND-053
...

Sheet TreeMap
A1: TreeMap : qui pèse le plus, et dans quelle catégorie
A2: Lecture : la TAILLE d’un carré = vues cumulées du créateur (portée) ; la COULEUR = catégorie de contenu ; le texte indique le taux d’engagement. Un grand carré n’est pas forcément un bon engagement : comparer les deux. Détail chiffré : onglet Catégories, section B.
B4: Autres (19 cr.) 272 M · 9,7 % | R4: Compte TND-051 222 M · 14,2 % | AE4: Compte TND-049 165 M · 10,8 % | AV4: Compte TND-008 80 M · 7,7 % | BE4: Compte TND-033 56 M · 16 %
BE9: TND-052 34 M · 17 % | BK9: TND-030 17 %
AV12: Autres (9 cr.) 58 M · 11 %
AE13: Autres (13 cr.) 147 M · 8,1 % | AO13: Compte TND-060 106 M · 14,8 %
BE14: TND-023 16 %
AV18: Autres (14 cr.) 81 M · 10,7 % | BF18: TND-010 74 M · 25 %
B19: Compte TND-073 200 M · 3,1 % | L19: Compte TND-028 141 M · 10,2 % | Y19: Compte TND-053 54 M · 8 %
AV25: Compte TND-003 45 M · 10 % | BB25: TND-037 18 %
Y26: TND-071 50 M · 20 % | AE26: Compte TND-004 101 M · 12,2 % | AN26: Compte TND-057 84 M · 14,4 % | BF26: TND-067 16 % | BJ26: Autres (3 cr.) 12 %
L28: Compte TND-013 109 M · 12,0 % | BB28: TND-014 20 %
AV31: Compte TND-042 43 M · 11 % | BD31: Autres (2 cr.) 10 % | BI31: @bts_official_bighit 36 %
Y33: TND-039 24 % | AC33: n°29
B37: Légende (couleur = catégorie ; entre parenthèses : part des vues du TreeMap)
E38: Humour & sketchs (26 %) | Z38: Animaux (6 %) | AU38: Famille & enfants (12 %)
E39: Food & lifestyle (5 %) | Z39: Musique & danse (4 %) | AU39: Non classé (46 %)
B41: Note : la disposition des carrés est calculée à partir des vues cumulées au moment de la construction du fichier ; les valeurs exactes se lisent dans l’onglet Catégories (section B). Les carrés trop petits portent un numéro (n°) qui renvoie à cette table.

Sheet Contacts
A1: Qui contacter : créateurs prioritaires d’après les analyses
A2: Sélection par règles chiffrées, sans donnée externe. Seuls les @noms des créateurs retenus ici sont communiqués.
A4: RÈGLES DE SÉLECTION
A5: ="A. Tendance : taux d’engagement cumulé ≥ 1,5 × la médiane ("&ROUND(1.5*Succès!E10*100,1)&" %) ET vues cumulées ≥ médiane d’une vidéo ("&ROUND(Succès!D10/1000000,1)&" M). Classés par engagement." -> A. Tendance : taux d’engagement cumulé ≥ 1,5 × la médiane (16 %) ET vues cumulées ≥ médiane d’une vidéo (10,4 M). Classés par engagement.
A6: ="B. Hashtag humour : taux d’engagement ≥ médiane du fichier ("&ROUND(Succès!E13*100,1)&" %) ET moins de 5 M d’abonnés : la taille de l’audience n’est pas ce qui fait le succès. Top 8 par engagement." -> B. Hashtag humour : taux d’engagement ≥ médiane du fichier (16,3 %) ET moins de 5 M d’abonnés : la taille de l’audience n’est pas ce qui fait le succès. Top 8 par engagement.
A8: A. CRÉATEURS EN TENDANCE À SUCCÈS CONFIRMÉ
A9: N° | B9: Compte | C9: Thème | D9: Nb vidéos | E9: Vues cumulées | F9: Taux d’engagement | G9: × médiane du fichier | H9: Compte vérifié | I9: Pourquoi le contacter | J9: Point de vigilance | K9: Réf. interne
A10: 1 | B10: @bts_official_bighit | C10: =INDEX(Données!$E$2:$E$101,MATCH(K10,Données!$C$2:$C$101,0)) -> Musique & danse | D10: =COUNTIF(Données!$C$2:$C$101,K10) -> 2 | E10: =SUMIF(Données!$C$2:$C$101,K10,Données!$L$2:$L$101) -> 26700000 | F10: =(SUMIF(Données!$C$2:$C$101,K10,Données!$M$2:$M$101)+SUMIF(Données!$C$2:$C$101,K10,Données!$N$2:$N$101)+SUMIF(Données!$C$2:$C$101,K10,Données!$O$2:$O$101))/E10 -> 0.3609176 | G10: =F10/Succès!$E$10 -> 3.3802707 | H10: =INDEX(Données!$F$2:$F$101,MATCH(K10,Données!$C$2:$C$101,0)) -> Oui | I10: 36,1 % d’engagement (3,4× la médiane), 27 M de vues sur 2 vidéos en tendance : régulier. | J10: Le nom du compte contient « official » : probablement une organisation, pas un créateur indépendant. Compte vérifié : vérifier qui gère les partenariats. | K10: TND-001
A11: 2 | B11: TND-010 | C11: =INDEX(Données!$E$2:$E$101,MATCH(K11,Données!$C$2:$C$101,0)) -> Food & lifestyle | D11: =COUNTIF(Données!$C$2:$C$101,K11) -> 3 | E11: =SUMIF(Données!$C$2:$C$101,K11,Données!$L$2:$L$101) -> 73900000 | F11: =(SUMIF(Données!$C$2:$C$101,K11,Données!$M$2:$M$101)+SUMIF(Données!$C$2:$C$101,K11,Données!$N$2:$N$101)+SUMIF(Données!$C$2:$C$101,K11,Données!$O$2:$O$101))/E11 -> 0.25065765 | G11: =F11/Succès!$E$10 -> 2.3476015 | H11: =INDEX(Données!$F$2:$F$101,MATCH(K11,Données!$C$2:$C$101,0)) -> Oui | I11: 25,1 % d’engagement (2,3× la médiane), 74 M de vues sur 3 vidéos en tendance : régulier. | J11: Compte vérifié : vérifier qui gère les partenariats. | K11: TND-010
A12: 3 | B12: TND-039 | C12: =INDEX(Données!$E$2:$E$101,MATCH(K12,Données!$C$2:$C$101,0)) -> Non classé | D12: =COUNTIF(Données!$C$2:$C$101,K12) -> 1 | E12: =SUMIF(Données!$C$2:$C$101,K12,Données!$L$2:$L$101) -> 14100000 | F12: =(SUMIF(Données!$C$2:$C$101,K12,Données!$M$2:$M$101)+SUMIF(Données!$C$2:$C$101,K12,Données!$N$2:$N$101)+SUMIF(Données!$C$2:$C$101,K12,Données!$O$2:$O$101))/E12 -> 0.23800709 | G12: =F12/Succès!$E$10 -> 2.2291193 | H12: =INDEX(Données!$F$2:$F$101,MATCH(K12,Données!$C$2:$C$101,0)) -> Inconnu | I12: 23,8 % d’engagement (2,2× la médiane), 14 M de vues sur 1 vidéo en tendance. | J12: Statut vérifié non disponible dans les extraits. | K12: TND-039
A13: 4 | B13: TND-071 | C13: =INDEX(Données!$E$2:$E$101,MATCH(K13,Données!$C$2:$C$101,0)) -> Non classé | D13: =COUNTIF(Données!$C$2:$C$101,K13) -> 1 | E13: =SUMIF(Données!$C$2:$C$101,K13,Données!$L$2:$L$101) -> 50500000 | F13: =(SUMIF(Données!$C$2:$C$101,K13,Données!$M$2:$M$101)+SUMIF(Données!$C$2:$C$101,K13,Données!$N$2:$N$101)+SUMIF(Données!$C$2:$C$101,K13,Données!$O$2:$O$101))/E13 -> 0.19853861 | G13: =F13/Succès!$E$10 -> 1.8594667 | H13: =INDEX(Données!$F$2:$F$101,MATCH(K13,Données!$C$2:$C$101,0)) -> Non | I13: 19,9 % d’engagement (1,9× la médiane), 50 M de vues sur 1 vidéo en tendance. | J13: Vérifier l’âge du créateur avant tout contact. | K13: TND-071
A14: 5 | B14: TND-014 | C14: =INDEX(Données!$E$2:$E$101,MATCH(K14,Données!$C$2:$C$101,0)) -> Animaux | D14: =COUNTIF(Données!$C$2:$C$101,K14) -> 1 | E14: =SUMIF(Données!$C$2:$C$101,K14,Données!$L$2:$L$101) -> 11400000 | F14: =(SUMIF(Données!$C$2:$C$101,K14,Données!$M$2:$M$101)+SUMIF(Données!$C$2:$C$101,K14,Données!$N$2:$N$101)+SUMIF(Données!$C$2:$C$101,K14,Données!$O$2:$O$101))/E14 -> 0.19607895 | G14: =F14/Succès!$E$10 -> 1.83643 | H14: =INDEX(Données!$F$2:$F$101,MATCH(K14,Données!$C$2:$C$101,0)) -> Non | I14: 19,6 % d’engagement (1,8× la médiane), 11 M de vues sur 1 vidéo en tendance. | J14: Vérifier l’âge du créateur avant tout contact. | K14: TND-014
A15: 6 | B15: TND-044 | C15: =INDEX(Données!$E$2:$E$101,MATCH(K15,Données!$C$2:$C$101,0)) -> Non classé | D15: =COUNTIF(Données!$C$2:$C$101,K15) -> 1 | E15: =SUMIF(Données!$C$2:$C$101,K15,Données!$L$2:$L$101) -> 10500000 | F15: =(SUMIF(Données!$C$2:$C$101,K15,Données!$M$2:$M$101)+SUMIF(Données!$C$2:$C$101,K15,Données!$N$2:$N$101)+SUMIF(Données!$C$2:$C$101,K15,Données!$O$2:$O$101))/E15 -> 0.18615238 | G15: =F15/Succès!$E$10 -> 1.7434601 | H15: =INDEX(Données!$F$2:$F$101,MATCH(K15,Données!$C$2:$C$101,0)) -> Inconnu | I15: 18,6 % d’engagement (1,7× la médiane), 10 M de vues sur 1 vidéo en tendance. | J15: Statut vérifié non disponible dans les extraits. | K15: TND-044
A16: 7 | B16: TND-037 | C16: =INDEX(Données!$E$2:$E$101,MATCH(K16,Données!$C$2:$C$101,0)) -> Animaux | D16: =COUNTIF(Données!$C$2:$C$101,K16) -> 1 | E16: =SUMIF(Données!$C$2:$C$101,K16,Données!$L$2:$L$101) -> 13200000 | F16: =(SUMIF(Données!$C$2:$C$101,K16,Données!$M$2:$M$101)+SUMIF(Données!$C$2:$C$101,K16,Données!$N$2:$N$101)+SUMIF(Données!$C$2:$C$101,K16,Données!$O$2:$O$101))/E16 -> 0.17941667 | G16: =F16/Succès!$E$10 -> 1.6803749 | H16: =INDEX(Données!$F$2:$F$101,MATCH(K16,Données!$C$2:$C$101,0)) -> Oui | I16: 17,9 % d’engagement (1,7× la médiane), 13 M de vues sur 1 vidéo en tendance. | J16: Compte vérifié : vérifier qui gère les partenariats. | K16: TND-037
A17: 8 | B17: TND-052 | C17: =INDEX(Données!$E$2:$E$101,MATCH(K17,Données!$C$2:$C$101,0)) -> Famille & enfants | D17: =COUNTIF(Données!$C$2:$C$101,K17) -> 1 | E17: =SUMIF(Données!$C$2:$C$101,K17,Données!$L$2:$L$101) -> 33500000 | F17: =(SUMIF(Données!$C$2:$C$101,K17,Données!$M$2:$M$101)+SUMIF(Données!$C$2:$C$101,K17,Données!$N$2:$N$101)+SUMIF(Données!$C$2:$C$101,K17,Données!$O$2:$O$101))/E17 -> 0.17048358 | G17: =F17/Succès!$E$10 -> 1.5967097 | H17: =INDEX(Données!$F$2:$F$101,MATCH(K17,Données!$C$2:$C$101,0)) -> Non | I17: 17,0 % d’engagement (1,6× la médiane), 34 M de vues sur 1 vidéo en tendance. | J17: Contenu famille : vérifier l’âge des personnes filmées et le consentement. | K17: TND-052
A18: 9 | B18: TND-030 | C18: =INDEX(Données!$E$2:$E$101,MATCH(K18,Données!$C$2:$C$101,0)) -> Famille & enfants | D18: =COUNTIF(Données!$C$2:$C$101,K18) -> 1 | E18: =SUMIF(Données!$C$2:$C$101,K18,Données!$L$2:$L$101) -> 25000000 | F18: =(SUMIF(Données!$C$2:$C$101,K18,Données!$M$2:$M$101)+SUMIF(Données!$C$2:$C$101,K18,Données!$N$2:$N$101)+SUMIF(Données!$C$2:$C$101,K18,Données!$O$2:$O$101))/E18 -> 0.166176 | G18: =F18/Succès!$E$10 -> 1.5563659 | H18: =INDEX(Données!$F$2:$F$101,MATCH(K18,Données!$C$2:$C$101,0)) -> Inconnu | I18: 16,6 % d’engagement (1,6× la médiane), 25 M de vues sur 1 vidéo en tendance. | J18: Statut vérifié non disponible dans les extraits. Contenu famille : vérifier l’âge des personnes filmées et le consentement. | K18: TND-030
A19: 10 | B19: TND-023 | C19: =INDEX(Données!$E$2:$E$101,MATCH(K19,Données!$C$2:$C$101,0)) -> Famille & enfants | D19: =COUNTIF(Données!$C$2:$C$101,K19) -> 1 | E19: =SUMIF(Données!$C$2:$C$101,K19,Données!$L$2:$L$101) -> 32200000 | F19: =(SUMIF(Données!$C$2:$C$101,K19,Données!$M$2:$M$101)+SUMIF(Données!$C$2:$C$101,K19,Données!$N$2:$N$101)+SUMIF(Données!$C$2:$C$101,K19,Données!$O$2:$O$101))/E19 -> 0.16485404 | G19: =F19/Succès!$E$10 -> 1.5439847 | H19: =INDEX(Données!$F$2:$F$101,MATCH(K19,Données!$C$2:$C$101,0)) -> Non | I19: 16,5 % d’engagement (1,5× la médiane), 32 M de vues sur 1 vidéo en tendance. | J19: Contenu famille : vérifier l’âge des personnes filmées et le consentement. | K19: TND-023
A20: 11 | B20: TND-067 | C20: =INDEX(Données!$E$2:$E$101,MATCH(K20,Données!$C$2:$C$101,0)) -> Food & lifestyle | D20: =COUNTIF(Données!$C$2:$C$101,K20) -> 1 | E20: =SUMIF(Données!$C$2:$C$101,K20,Données!$L$2:$L$101) -> 24900000 | F20: =(SUMIF(Données!$C$2:$C$101,K20,Données!$M$2:$M$101)+SUMIF(Données!$C$2:$C$101,K20,Données!$N$2:$N$101)+SUMIF(Données!$C$2:$C$101,K20,Données!$O$2:$O$101))/E20 -> 0.16186747 | G20: =F20/Succès!$E$10 -> 1.5160132 | H20: =INDEX(Données!$F$2:$F$101,MATCH(K20,Données!$C$2:$C$101,0)) -> Inconnu | I20: 16,2 % d’engagement (1,5× la médiane), 25 M de vues sur 1 vidéo en tendance. | J20: Statut vérifié non disponible dans les extraits. | K20: TND-067
A22: B. PETITS ET MOYENS COMPTES À FORT ENGAGEMENT (hashtag humour)
A23: N° | B23: Compte | C23: Abonnés | D23: Nb vidéos | E23: Vues | F23: Taux d’engagement | G23: × médiane du fichier | H23: Compte vérifié | I23: Pourquoi le contacter | J23: Point de vigilance | K23: Réf. interne
A24: 1 | B24: HSH-042 | C24: =INDEX(Données!$G$302:$G$401,MATCH(K24,Données!$C$302:$C$401,0)) -> 499800 | D24: =COUNTIF(Données!$C$302:$C$401,K24) -> 1 | E24: =SUMIF(Données!$C$302:$C$401,K24,Données!$L$302:$L$401) -> 28800000 | F24: =(SUMIF(Données!$C$302:$C$401,K24,Données!$M$302:$M$401)+SUMIF(Données!$C$302:$C$401,K24,Données!$N$302:$N$401)+SUMIF(Données!$C$302:$C$401,K24,Données!$O$302:$O$401))/E24 -> 0.29521528 | G24: =F24/Succès!$E$13 -> 1.8057392 | H24: =INDEX(Données!$F$302:$F$401,MATCH(K24,Données!$C$302:$C$401,0)) -> Non | I24: 29,5 % d’engagement (1,8× la médiane du fichier) pour 500 k abonnés : 58 vues par abonné. | J24: Vérifier l’âge du créateur avant tout contact. | K24: HSH-042
A25: 2 | B25: HSH-077 | C25: =INDEX(Données!$G$302:$G$401,MATCH(K25,Données!$C$302:$C$401,0)) -> 958100 | D25: =COUNTIF(Données!$C$302:$C$401,K25) -> 1 | E25: =SUMIF(Données!$C$302:$C$401,K25,Données!$L$302:$L$401) -> 27700000 | F25: =(SUMIF(Données!$C$302:$C$401,K25,Données!$M$302:$M$401)+SUMIF(Données!$C$302:$C$401,K25,Données!$N$302:$N$401)+SUMIF(Données!$C$302:$C$401,K25,Données!$O$302:$O$401))/E25 -> 0.25846209 | G25: =F25/Succès!$E$13 -> 1.5809315 | H25: =INDEX(Données!$F$302:$F$401,MATCH(K25,Données!$C$302:$C$401,0)) -> Non | I25: 25,8 % d’engagement (1,6× la médiane du fichier) pour 958 k abonnés : 29 vues par abonné. | J25: Vérifier l’âge du créateur avant tout contact. | K25: HSH-077
A26: 3 | B26: HSH-013 | C26: =INDEX(Données!$G$302:$G$401,MATCH(K26,Données!$C$302:$C$401,0)) -> 144200 | D26: =COUNTIF(Données!$C$302:$C$401,K26) -> 1 | E26: =SUMIF(Données!$C$302:$C$401,K26,Données!$L$302:$L$401) -> 46100000 | F26: =(SUMIF(Données!$C$302:$C$401,K26,Données!$M$302:$M$401)+SUMIF(Données!$C$302:$C$401,K26,Données!$N$302:$N$401)+SUMIF(Données!$C$302:$C$401,K26,Données!$O$302:$O$401))/E26 -> 0.25637093 | G26: =F26/Succès!$E$13 -> 1.5681405 | H26: =INDEX(Données!$F$302:$F$401,MATCH(K26,Données!$C$302:$C$401,0)) -> Non | I26: 25,6 % d’engagement (1,6× la médiane du fichier) pour 144 k abonnés : 320 vues par abonné. | J26: Vérifier l’âge du créateur avant tout contact. | K26: HSH-013
A27: 4 | B27: HSH-057 | C27: =INDEX(Données!$G$302:$G$401,MATCH(K27,Données!$C$302:$C$401,0)) -> 1300000 | D27: =COUNTIF(Données!$C$302:$C$401,K27) -> 1 | E27: =SUMIF(Données!$C$302:$C$401,K27,Données!$L$302:$L$401) -> 34000000 | F27: =(SUMIF(Données!$C$302:$C$401,K27,Données!$M$302:$M$401)+SUMIF(Données!$C$302:$C$401,K27,Données!$N$302:$N$401)+SUMIF(Données!$C$302:$C$401,K27,Données!$O$302:$O$401))/E27 -> 0.23399706 | G27: =F27/Succès!$E$13 -> 1.4312865 | H27: =INDEX(Données!$F$302:$F$401,MATCH(K27,Données!$C$302:$C$401,0)) -> Non | I27: 23,4 % d’engagement (1,4× la médiane du fichier) pour 1,30 M abonnés : 26 vues par abonné. | J27: Vérifier l’âge du créateur avant tout contact. | K27: HSH-057
A28: 5 | B28: HSH-009 | C28: =INDEX(Données!$G$302:$G$401,MATCH(K28,Données!$C$302:$C$401,0)) -> 168400 | D28: =COUNTIF(Données!$C$302:$C$401,K28) -> 1 | E28: =SUMIF(Données!$C$302:$C$401,K28,Données!$L$302:$L$401) -> 59400000 | F28: =(SUMIF(Données!$C$302:$C$401,K28,Données!$M$302:$M$401)+SUMIF(Données!$C$302:$C$401,K28,Données!$N$302:$N$401)+SUMIF(Données!$C$302:$C$401,K28,Données!$O$302:$O$401))/E28 -> 0.23341077 | G28: =F28/Succès!$E$13 -> 1.4277004 | H28: =INDEX(Données!$F$302:$F$401,MATCH(K28,Données!$C$302:$C$401,0)) -> Non | I28: 23,3 % d’engagement (1,4× la médiane du fichier) pour 168 k abonnés : 353 vues par abonné. | J28: Vérifier l’âge du créateur avant tout contact. | K28: HSH-009
A29: 6 | B29: HSH-018 | C29: =INDEX(Données!$G$302:$G$401,MATCH(K29,Données!$C$302:$C$401,0)) -> 1000000 | D29: =COUNTIF(Données!$C$302:$C$401,K29) -> 1 | E29: =SUMIF(Données!$C$302:$C$401,K29,Données!$L$302:$L$401) -> 44200000 | F29: =(SUMIF(Données!$C$302:$C$401,K29,Données!$M$302:$M$401)+SUMIF(Données!$C$302:$C$401,K29,Données!$N$302:$N$401)+SUMIF(Données!$C$302:$C$401,K29,Données!$O$302:$O$401))/E29 -> 0.23197964 | G29: =F29/Succès!$E$13 -> 1.4189466 | H29: =INDEX(Données!$F$302:$F$401,MATCH(K29,Données!$C$302:$C$401,0)) -> Non | I29: 23,2 % d’engagement (1,4× la médiane du fichier) pour 1,00 M abonnés : 44 vues par abonné. | J29: Vérifier l’âge du créateur avant tout contact. | K29: HSH-018
A30: 7 | B30: HSH-025 | C30: =INDEX(Données!$G$302:$G$401,MATCH(K30,Données!$C$302:$C$401,0)) -> 158600 | D30: =COUNTIF(Données!$C$302:$C$401,K30) -> 1 | E30: =SUMIF(Données!$C$302:$C$401,K30,Données!$L$302:$L$401) -> 42800000 | F30: =(SUMIF(Données!$C$302:$C$401,K30,Données!$M$302:$M$401)+SUMIF(Données!$C$302:$C$401,K30,Données!$N$302:$N$401)+SUMIF(Données!$C$302:$C$401,K30,Données!$O$302:$O$401))/E30 -> 0.22969159 | G30: =F30/Succès!$E$13 -> 1.4049513 | H30: =INDEX(Données!$F$302:$F$401,MATCH(K30,Données!$C$302:$C$401,0)) -> Non | I30: 23,0 % d’engagement (1,4× la médiane du fichier) pour 159 k abonnés : 270 vues par abonné. | J30: Vérifier l’âge du créateur avant tout contact. | K30: HSH-025
A31: 8 | B31: HSH-067 | C31: =INDEX(Données!$G$302:$G$401,MATCH(K31,Données!$C$302:$C$401,0)) -> 74300 | D31: =COUNTIF(Données!$C$302:$C$401,K31) -> 1 | E31: =SUMIF(Données!$C$302:$C$401,K31,Données!$L$302:$L$401) -> 31500000 | F31: =(SUMIF(Données!$C$302:$C$401,K31,Données!$M$302:$M$401)+SUMIF(Données!$C$302:$C$401,K31,Données!$N$302:$N$401)+SUMIF(Données!$C$302:$C$401,K31,Données!$O$302:$O$401))/E31 -> 0.22853016 | G31: =F31/Succès!$E$13 -> 1.3978472 | H31: =INDEX(Données!$F$302:$F$401,MATCH(K31,Données!$C$302:$C$401,0)) -> Non | I31: 22,9 % d’engagement (1,4× la médiane du fichier) pour 74 k abonnés : 424 vues par abonné. | J31: Vérifier l’âge du créateur avant tout contact. | K31: HSH-067

Sheet Méthode
A1: Méthode, données personnelles et limites
A2: Ce que le fichier utilise, ce qu’il écarte, et pourquoi.
A3: 1. SOURCES : LES EXTRAITS UTILISÉS
A4: Extrait | B4: Usage | C4: Remarque
A5: trending_videos1 | B5: Fichier principal | C5: 100 vidéos, 84 créateurs : vues, J’aime, commentaires, partages, durée, légende.
A6: trending_authors1 | B6: Statut « vérifié » uniquement | C6: Aucune mesure de performance ; ne couvre que 44 des 100 vidéos en tendance (les autres : « Inconnu »). Biographies, liens, avatars non repris.
A7: tiktok_collected_liked_vide | B7: Contrôle de robustesse | C7: Sélection éditoriale d’un compte : jamais fusionnée avec les autres.
A8: tiktok_collected_videos1 | B8: Repère contenu de marque | C8: Un seul compte (le compte officiel de la plateforme).
A9: tiktok_funny_hashtag_videos | B9: Test de la taille d’audience | C9: Seul fichier avec les abonnés. La colonne « video_stats » est lue comme le nombre de J’aime (ordre de grandeur cohérent avec les vues, toujours ≤ vues).
A11: 2. RÈGLES DE CALCUL
A12: Taux d’engagement | B12: (J’aime + commentaires + partages) ÷ vues. Les compteurs ≥ 1 000 sont arrondis par la plateforme : précision de quelques % près.
A13: Seuils | B13: Médianes de chaque fichier (voir onglet Succès). Aucune comparaison de valeurs absolues entre fichiers.
A14: Catégories | B14: Mots-clés cherchés dans les légendes et hashtags (animaux, famille, nourriture, musique, humour, dans cet ordre de priorité). Le thème d’un créateur est le plus fréquent parmi ses vidéos classées. Aucune attribution manuelle ni connaissance extérieure aux tableaux : classification indicative.
A15: Hashtag générique | B15: Légende contenant #fyp, #foryou, #foryoupage, #viral, #parati, #xyzbca, #fy, #4u, #trending ou #fypシ.
A16: TreeMap | B16: Dessiné en cellules à partir des vues cumulées par créateur (algorithme « squarified »). Les créateurs non retenus pour le contact sont regroupés par catégorie ou désignés par une référence.
A18: 3. DONNÉES PERSONNELLES
A19: Conservé | B19: Version publique : les @ des créateurs sont remplacés par leurs références internes, sauf le compte d’organisation BTS. Version de travail : @ des 19 créateurs proposés au contact (finalité : choisir des partenaires), références anonymes (TND-xxx, AIM-xxx, HSH-xxx) pour tous les autres, mesures de performance agrégées ou par vidéo.
A20: Retiré | B20: Identifiants numériques des comptes, vidéos et musiques, pseudos affichés, biographies, photos de profil, liens vers vidéos, vignettes et sons, légendes complètes, indicateurs de compte privé.
A21: À valider | B21: Les contenus publics restent des données personnelles : valider la finalité et la durée de conservation avec le DPO ; extraction de 2021 à purger ou actualiser.
A23: 4. CE QUE CES DONNÉES NE PEUVENT PAS DIRE
A24: • Aucune vidéo peu performante : les extraits ne contiennent que du contenu mis en avant. On compare des succès entre eux ; on ne sait pas ce qui sépare un succès d’un échec.
A25: • Corrélations, pas causalité : changer un réglage (durée, légende…) ne garantit pas le même résultat.
A26: • Aucun résultat business (ventes, notoriété, coût, sécurité de marque) : l’engagement n’est pas la conversion.
A27: • Instantané de mai à août 2021 ; échantillons de 100 vidéos : écarts entre catégories indicatifs. Abonnés disponibles pour le seul fichier hashtag.

Sheet Données
A1: Source | B1: Réf. vidéo | C1: Réf. créateur | D1: Compte (si retenu pour contact) | E1: Thème du créateur | F1: Compte vérifié | G1: Abonnés | H1: Durée (s) | I1: Nb hashtags | J1: Longueur légende (car.) | K1: Hashtag générique (1/0) | L1: Vues | M1: J’aime | N1: Commentaires | O1: Partages | P1: Taux d’engagement | Q1: Taux de J’aime | R1: Vues par abonné | S1: Profil | T1: Succès complet (1/0)
A2: Tendance | B2: T001 | C2: TND-001 | D2: @bts_official_bighit | E2: Musique & danse | F2: Oui | H2: 18 | I2: 2 | J2: 26 | K2: 0 | L2: 9700000 | M2: 3600000 | N2: 212900 | O2: 109500 | P2: =(M2+N2+O2)/L2 -> 0.40437113 | Q2: =M2/L2 -> 0.37113402 | R2: =IF(G2="","",L2/G2) | S2: =IF(AND(L2>=INDEX(Succès!$D$10:$D$13,MATCH(A2,Succès!$A$10:$A$13,0)),P2>=INDEX(Succès!$E$10:$E$13,MATCH(A2,Succès!$A$10:$A$13,0))),"Succès complet",IF(P2>=INDEX(Succès!$E$10:$E$13,MATCH(A2,Succès!$A$10:$A$13,0)),"Engagé, portée modeste",IF(L2>=INDEX(Succès!$D$10:$D$13,MATCH(A2,Succès!$A$10:$A$13,0)),"Portée sans engagement","Standard"))) -> Engagé, portée modeste | T2: =IF(S2="Succès complet",1,0) -> 0
